OperationalError
sqlalchemy.exc.OperationalError: (sqlite3.OperationalError) no such column: user.is_admin
[SQL: SELECT user.id AS user_id, user.username AS user_username, user.email AS user_email, user.password_hash AS user_password_hash, user.is_online AS user_is_online, user.status AS user_status, user.custom_status AS user_custom_status, user.status_emoji AS user_status_emoji, user.last_seen AS user_last_seen, user.role AS user_role, user.is_admin AS user_is_admin, user.join_date AS user_join_date, user.bio AS user_bio 
FROM user 
WHERE user.id = ?]
[parameters: (1,)]
(Background on this error at: https://sqlalche.me/e/20/e3q8)

Traceback (most recent call last)
File "/home/runner/TeamFlow-1/.pythonlibs/lib/python3.11/site-packages/sqlalchemy/engine/base.py", line 1967, in _exec_single_context
self.dialect.do_execute(
^
File "/home/runner/TeamFlow-1/.pythonlibs/lib/python3.11/site-packages/sqlalchemy/engine/default.py", line 941, in do_execute
cursor.execute(statement, parameters)
^^^^^^^^^^^^^^^^^^^^^^^^^^^^^^^^^^^^^
The above exception was the direct cause of the following exception:
File "/home/runner/TeamFlow-1/.pythonlibs/lib/python3.11/site-packages/flask/app.py", line 1536, in __call__
return self.wsgi_app(environ, start_response)
       ^^^^^^^^^^^^^^^^^^^^^^^^^^^^^^^^^^^^^^
File "/home/runner/TeamFlow-1/.pythonlibs/lib/python3.11/site-packages/flask_socketio/__init__.py", line 42, in __call__
return super().__call__(environ, start_response)
       ^^^^^^^^^^^^^^^^^^^^^^^^^^^^^^^^^^^^^^^^^
File "/home/runner/TeamFlow-1/.pythonlibs/lib/python3.11/site-packages/engineio/middleware.py", line 74, in __call__
return self.wsgi_app(environ, start_response)
       ^^^^^^^^^^^^^^^^^^^^^^^^^^^^^^^^^^^^^^
File "/home/runner/TeamFlow-1/.pythonlibs/lib/python3.11/site-packages/flask/app.py", line 1514, in wsgi_app
response = self.handle_exception(e)
           ^^^^^^^^^^^^^^^^^^^^^^^^
File "/home/runner/TeamFlow-1/.pythonlibs/lib/python3.11/site-packages/flask/app.py", line 1511, in wsgi_app
response = self.full_dispatch_request()
           ^^^^^^^^^^^^^^^^^^^^^^^^^^^^
File "/home/runner/TeamFlow-1/.pythonlibs/lib/python3.11/site-packages/flask/app.py", line 919, in full_dispatch_request
rv = self.handle_user_exception(e)
     ^^^^^^^^^^^^^^^^^^^^^^^^^^^^^
File "/home/runner/TeamFlow-1/.pythonlibs/lib/python3.11/site-packages/flask/app.py", line 917, in full_dispatch_request
rv = self.dispatch_request()
     ^^^^^^^^^^^^^^^^^^^^^^^
File "/home/runner/TeamFlow-1/.pythonlibs/lib/python3.11/site-packages/flask/app.py", line 902, in dispatch_request
return self.ensure_sync(self.view_functions[rule.endpoint])(**view_args)  # type: ignore[no-any-return]
       ^^^^^^^^^^^^^^^^^^^^^^^^^^^^^^^^^^^^^^^^^^^^^^^^^^^^^^^^^^^^^^^^^
File "/home/runner/TeamFlow-1/app.py", line 63, in index
if current_user.is_authenticated:
   ^^^^^^^^^^^^^^^^^^^^^^^^^^^^^
File "/home/runner/TeamFlow-1/.pythonlibs/lib/python3.11/site-packages/werkzeug/local.py", line 318, in __get__
obj = instance._get_current_object()
      ^^^^^^^^^^^^^^^^^^^^^^^^^^^^^^
File "/home/runner/TeamFlow-1/.pythonlibs/lib/python3.11/site-packages/werkzeug/local.py", line 526, in _get_current_object
return get_name(local())
                ^^^^^^^
File "/home/runner/TeamFlow-1/.pythonlibs/lib/python3.11/site-packages/flask_login/utils.py", line 25, in <lambda>
current_user = LocalProxy(lambda: _get_user())
                                  ^^^^^^^^^^^
File "/home/runner/TeamFlow-1/.pythonlibs/lib/python3.11/site-packages/flask_login/utils.py", line 370, in _get_user
current_app.login_manager._load_user()
^^^^^^^^^^^^^^^^^^^^^^^^^^^^^^^^^^^^^^
File "/home/runner/TeamFlow-1/.pythonlibs/lib/python3.11/site-packages/flask_login/login_manager.py", line 364, in _load_user
user = self._user_callback(user_id)
       ^^^^^^^^^^^^^^^^^^^^^^^^^^^^
File "/home/runner/TeamFlow-1/app.py", line 58, in load_user
return User.query.get(int(user_id))
       ^^^^^^^^^^^^^^^^^^^^^^^^^^^^
File "<string>", line 2, in get
File "/home/runner/TeamFlow-1/.pythonlibs/lib/python3.11/site-packages/sqlalchemy/util/deprecations.py", line 386, in warned
return fn(*args, **kwargs)  # type: ignore[no-any-return]
       ^^^^^^^^^^^^^^^^^^^
File "/home/runner/TeamFlow-1/.pythonlibs/lib/python3.11/site-packages/sqlalchemy/orm/query.py", line 1127, in get
return self._get_impl(ident, loading.load_on_pk_identity)
       ^^^^^^^^^^^^^^^^^^^^^^^^^^^^^^^^^^^^^^^^^^^^^^^^^^
File "/home/runner/TeamFlow-1/.pythonlibs/lib/python3.11/site-packages/sqlalchemy/orm/query.py", line 1136, in _get_impl
return self.session._get_impl(
       
File "/home/runner/TeamFlow-1/.pythonlibs/lib/python3.11/site-packages/sqlalchemy/orm/session.py", line 3873, in _get_impl
return db_load_fn(
       
File "/home/runner/TeamFlow-1/.pythonlibs/lib/python3.11/site-packages/sqlalchemy/orm/loading.py", line 694, in load_on_pk_identity
session.execute(
^
File "/home/runner/TeamFlow-1/.pythonlibs/lib/python3.11/site-packages/sqlalchemy/orm/session.py", line 2362, in execute
return self._execute_internal(
       
File "/home/runner/TeamFlow-1/.pythonlibs/lib/python3.11/site-packages/sqlalchemy/orm/session.py", line 2247, in _execute_internal
result: Result[Any] = compile_state_cls.orm_execute_statement(
                      
File "/home/runner/TeamFlow-1/.pythonlibs/lib/python3.11/site-packages/sqlalchemy/orm/context.py", line 305, in orm_execute_statement
result = conn.execute(
         
File "/home/runner/TeamFlow-1/.pythonlibs/lib/python3.11/site-packages/sqlalchemy/engine/base.py", line 1418, in execute
return meth(
       
File "/home/runner/TeamFlow-1/.pythonlibs/lib/python3.11/site-packages/sqlalchemy/sql/elements.py", line 515, in _execute_on_connection
return connection._execute_clauseelement(
       
File "/home/runner/TeamFlow-1/.pythonlibs/lib/python3.11/site-packages/sqlalchemy/engine/base.py", line 1640, in _execute_clauseelement
ret = self._execute_context(
      
File "/home/runner/TeamFlow-1/.pythonlibs/lib/python3.11/site-packages/sqlalchemy/engine/base.py", line 1846, in _execute_context
return self._exec_single_context(
       
File "/home/runner/TeamFlow-1/.pythonlibs/lib/python3.11/site-packages/sqlalchemy/engine/base.py", line 1986, in _exec_single_context
self._handle_dbapi_exception(
^
File "/home/runner/TeamFlow-1/.pythonlibs/lib/python3.11/site-packages/sqlalchemy/engine/base.py", line 2355, in _handle_dbapi_exception
raise sqlalchemy_exception.with_traceback(exc_info[2]) from e
^^^^^^^^^^^^^^^^^^^^^^^^^^^^^^^^^^^^^^^^^^^^^^^^^^^^^^^^^^^^^
File "/home/runner/TeamFlow-1/.pythonlibs/lib/python3.11/site-packages/sqlalchemy/engine/base.py", line 1967, in _exec_single_context
self.dialect.do_execute(
^
File "/home/runner/TeamFlow-1/.pythonlibs/lib/python3.11/site-packages/sqlalchemy/engine/default.py", line 941, in do_execute
cursor.execute(statement, parameters)
^^^^^^^^^^^^^^^^^^^^^^^^^^^^^^^^^^^^^
sqlalchemy.exc.OperationalError: (sqlite3.OperationalError) no such column: user.is_admin
[SQL: SELECT user.id AS user_id, user.username AS user_username, user.email AS user_email, user.password_hash AS user_password_hash, user.is_online AS user_is_online, user.status AS user_status, user.custom_status AS user_custom_status, user.status_emoji AS user_status_emoji, user.last_seen AS user_last_seen, user.role AS user_role, user.is_admin AS user_is_admin, user.join_date AS user_join_date, user.bio AS user_bio
FROM user
WHERE user.id = ?]
[parameters: (1,)]
(Background on this error at: https://sqlalche.me/e/20/e3q8)
The debugger caught an exception in your WSGI application. You can now look at the traceback which led to the error.
To switch between the interactive traceback and the plaintext one, you can click on the "Traceback" headline. From the text traceback you can also create a paste of it.

